<?xml version="1.0"?>
<!-- Base URDF for simple bipedal humanoid robot with 6-12 DOF legs -->
<robot name="simple_humanoid">

  <!-- Base/Fixed link representing the torso -->
  <link name="base_link">
    <visual>
      <geometry>
        <box size="0.3 0.2 0.5"/>
      </geometry>
      <material name="grey">
        <color rgba="0.5 0.5 0.5 1.0"/>
      </material>
    </visual>
    <collision>
      <geometry>
        <box size="0.3 0.2 0.5"/>
      </geometry>
    </collision>
    <inertial>
      <mass value="10.0"/>
      <inertia ixx="0.1" ixy="0.0" ixz="0.0" iyy="0.2" iyz="0.0" izz="0.15"/>
    </inertial>
  </link>

  <!-- Head link -->
  <link name="head">
    <visual>
      <geometry>
        <sphere radius="0.1"/>
      </geometry>
      <material name="white">
        <color rgba="1.0 1.0 1.0 1.0"/>
      </material>
    </visual>
    <collision>
      <geometry>
        <sphere radius="0.1"/>
      </geometry>
    </collision>
    <inertial>
      <mass value="1.0"/>
      <inertia ixx="0.001" ixy="0.0" ixz="0.0" iyy="0.001" iyz="0.0" izz="0.001"/>
    </inertial>
  </link>

  <joint name="head_joint" type="revolute">
    <parent link="base_link"/>
    <child link="head"/>
    <origin xyz="0 0 0.35" rpy="0 0 0"/>
    <axis xyz="0 1 0"/>
    <limit lower="-0.5" upper="0.5" effort="10.0" velocity="1.0"/>
  </joint>

  <!-- Left Leg -->
  <link name="left_hip">
    <visual>
      <geometry>
        <box size="0.1 0.1 0.2"/>
      </geometry>
      <material name="blue">
        <color rgba="0.0 0.0 1.0 1.0"/>
      </material>
    </visual>
    <collision>
      <geometry>
        <box size="0.1 0.1 0.2"/>
      </geometry>
    </collision>
    <inertial>
      <mass value="1.0"/>
      <inertia ixx="0.001" ixy="0.0" ixz="0.0" iyy="0.001" iyz="0.0" izz="0.001"/>
    </inertial>
  </link>

  <joint name="left_hip_joint" type="revolute">
    <parent link="base_link"/>
    <child link="left_hip"/>
    <origin xyz="-0.1 0 -0.25" rpy="0 0 0"/>
    <axis xyz="1 0 0"/>
    <limit lower="-0.5" upper="0.5" effort="10.0" velocity="1.0"/>
  </joint>

  <link name="left_knee">
    <visual>
      <geometry>
        <box size="0.1 0.1 0.3"/>
      </geometry>
      <material name="blue">
        <color rgba="0.0 0.0 1.0 1.0"/>
      </material>
    </visual>
    <collision>
      <geometry>
        <box size="0.1 0.1 0.3"/>
      </geometry>
    </collision>
    <inertial>
      <mass value="1.0"/>
      <inertia ixx="0.001" ixy="0.0" ixz="0.0" iyy="0.001" iyz="0.0" izz="0.001"/>
    </inertial>
  </link>

  <joint name="left_knee_joint" type="revolute">
    <parent link="left_hip"/>
    <child link="left_knee"/>
    <origin xyz="0 0 -0.15" rpy="0 0 0"/>
    <axis xyz="1 0 0"/>
    <limit lower="0" upper="1.57" effort="10.0" velocity="1.0"/>
  </joint>

  <link name="left_ankle">
    <visual>
      <geometry>
        <box size="0.15 0.1 0.05"/>
      </geometry>
      <material name="blue">
        <color rgba="0.0 0.0 1.0 1.0"/>
      </material>
    </visual>
    <collision>
      <geometry>
        <box size="0.15 0.1 0.05"/>
      </geometry>
    </collision>
    <inertial>
      <mass value="0.5"/>
      <inertia ixx="0.0001" ixy="0.0" ixz="0.0" iyy="0.0001" iyz="0.0" izz="0.0001"/>
    </inertial>
  </link>

  <joint name="left_ankle_joint" type="revolute">
    <parent link="left_knee"/>
    <child link="left_ankle"/>
    <origin xyz="0 0 -0.15" rpy="0 0 0"/>
    <axis xyz="1 0 0"/>
    <limit lower="-0.5" upper="0.5" effort="5.0" velocity="1.0"/>
  </joint>

  <!-- Right Leg -->
  <link name="right_hip">
    <visual>
      <geometry>
        <box size="0.1 0.1 0.2"/>
      </geometry>
      <material name="red">
        <color rgba="1.0 0.0 0.0 1.0"/>
      </material>
    </visual>
    <collision>
      <geometry>
        <box size="0.1 0.1 0.2"/>
      </geometry>
    </collision>
    <inertial>
      <mass value="1.0"/>
      <inertia ixx="0.001" ixy="0.0" ixz="0.0" iyy="0.001" iyz="0.0" izz="0.001"/>
    </inertial>
  </link>

  <joint name="right_hip_joint" type="revolute">
    <parent link="base_link"/>
    <child link="right_hip"/>
    <origin xyz="0.1 0 -0.25" rpy="0 0 0"/>
    <axis xyz="1 0 0"/>
    <limit lower="-0.5" upper="0.5" effort="10.0" velocity="1.0"/>
  </joint>

  <link name="right_knee">
    <visual>
      <geometry>
        <box size="0.1 0.1 0.3"/>
      </geometry>
      <material name="red">
        <color rgba="1.0 0.0 0.0 1.0"/>
      </material>
    </visual>
    <collision>
      <geometry>
        <box size="0.1 0.1 0.3"/>
      </geometry>
    </collision>
    <inertial>
      <mass value="1.0"/>
      <inertia ixx="0.001" ixy="0.0" ixz="0.0" iyy="0.001" iyz="0.0" izz="0.001"/>
    </inertial>
  </link>

  <joint name="right_knee_joint" type="revolute">
    <parent link="right_hip"/>
    <child link="right_knee"/>
    <origin xyz="0 0 -0.15" rpy="0 0 0"/>
    <axis xyz="1 0 0"/>
    <limit lower="0" upper="1.57" effort="10.0" velocity="1.0"/>
  </joint>

  <link name="right_ankle">
    <visual>
      <geometry>
        <box size="0.15 0.1 0.05"/>
      </geometry>
      <material name="red">
        <color rgba="1.0 0.0 0.0 1.0"/>
      </material>
    </visual>
    <collision>
      <geometry>
        <box size="0.15 0.1 0.05"/>
      </geometry>
    </collision>
    <inertial>
      <mass value="0.5"/>
      <inertia ixx="0.0001" ixy="0.0" ixz="0.0" iyy="0.0001" iyz="0.0" izz="0.0001"/>
    </inertial>
  </link>

  <joint name="right_ankle_joint" type="revolute">
    <parent link="right_knee"/>
    <child link="right_ankle"/>
    <origin xyz="0 0 -0.15" rpy="0 0 0"/>
    <axis xyz="1 0 0"/>
    <limit lower="-0.5" upper="0.5" effort="5.0" velocity="1.0"/>
  </joint>

  <!-- Left Arm -->
  <link name="left_shoulder">
    <visual>
      <geometry>
        <box size="0.1 0.1 0.15"/>
      </geometry>
      <material name="green">
        <color rgba="0.0 1.0 0.0 1.0"/>
      </material>
    </visual>
    <collision>
      <geometry>
        <box size="0.1 0.1 0.15"/>
      </geometry>
    </collision>
    <inertial>
      <mass value="0.8"/>
      <inertia ixx="0.0005" ixy="0.0" ixz="0.0" iyy="0.0005" iyz="0.0" izz="0.0005"/>
    </inertial>
  </link>

  <joint name="left_shoulder_joint" type="revolute">
    <parent link="base_link"/>
    <child link="left_shoulder"/>
    <origin xyz="-0.15 0 0.1" rpy="0 0 0"/>
    <axis xyz="0 1 0"/>
    <limit lower="-1.57" upper="1.57" effort="5.0" velocity="1.0"/>
  </joint>

  <link name="left_elbow">
    <visual>
      <geometry>
        <box size="0.08 0.08 0.25"/>
      </geometry>
      <material name="green">
        <color rgba="0.0 1.0 0.0 1.0"/>
      </material>
    </visual>
    <collision>
      <geometry>
        <box size="0.08 0.08 0.25"/>
      </geometry>
    </collision>
    <inertial>
      <mass value="0.6"/>
      <inertia ixx="0.0005" ixy="0.0" ixz="0.0" iyy="0.0005" iyz="0.0" izz="0.0005"/>
    </inertial>
  </link>

  <joint name="left_elbow_joint" type="revolute">
    <parent link="left_shoulder"/>
    <child link="left_elbow"/>
    <origin xyz="0 0 -0.1" rpy="0 0 0"/>
    <axis xyz="1 0 0"/>
    <limit lower="-1.57" upper="1.57" effort="5.0" velocity="1.0"/>
  </joint>

  <!-- Right Arm -->
  <link name="right_shoulder">
    <visual>
      <geometry>
        <box size="0.1 0.1 0.15"/>
      </geometry>
      <material name="yellow">
        <color rgba="1.0 1.0 0.0 1.0"/>
      </material>
    </visual>
    <collision>
      <geometry>
        <box size="0.1 0.1 0.15"/>
      </geometry>
    </collision>
    <inertial>
      <mass value="0.8"/>
      <inertia ixx="0.0005" ixy="0.0" ixz="0.0" iyy="0.0005" iyz="0.0" izz="0.0005"/>
    </inertial>
  </link>

  <joint name="right_shoulder_joint" type="revolute">
    <parent link="base_link"/>
    <child link="right_shoulder"/>
    <origin xyz="0.15 0 0.1" rpy="0 0 0"/>
    <axis xyz="0 1 0"/>
    <limit lower="-1.57" upper="1.57" effort="5.0" velocity="1.0"/>
  </joint>

  <link name="right_elbow">
    <visual>
      <geometry>
        <box size="0.08 0.08 0.25"/>
      </geometry>
      <material name="yellow">
        <color rgba="1.0 1.0 0.0 1.0"/>
      </material>
    </visual>
    <collision>
      <geometry>
        <box size="0.08 0.08 0.25"/>
      </geometry>
    </collision>
    <inertial>
      <mass value="0.6"/>
      <inertia ixx="0.0005" ixy="0.0" ixz="0.0" iyy="0.0005" iyz="0.0" izz="0.0005"/>
    </inertial>
  </link>

  <joint name="right_elbow_joint" type="revolute">
    <parent link="right_shoulder"/>
    <child link="right_elbow"/>
    <origin xyz="0 0 -0.1" rpy="0 0 0"/>
    <axis xyz="1 0 0"/>
    <limit lower="-1.57" upper="1.57" effort="5.0" velocity="1.0"/>
  </joint>

  <!-- Sensors -->
  <link name="imu_link">
    <visual>
      <geometry>
        <box size="0.02 0.02 0.02"/>
      </geometry>
      <material name="black">
        <color rgba="0.0 0.0 0.0 1.0"/>
      </material>
    </visual>
    <inertial>
      <mass value="0.01"/>
      <inertia ixx="1e-6" ixy="0.0" ixz="0.0" iyy="1e-6" iyz="0.0" izz="1e-6"/>
    </inertial>
  </link>

  <joint name="imu_joint" type="fixed">
    <parent link="base_link"/>
    <child link="imu_link"/>
    <origin xyz="0 0 0.2" rpy="0 0 0"/>
  </joint>

  <!-- Gazebo plugin for ROS control -->
  <gazebo>
    <plugin name="gazebo_ros_control" filename="libgazebo_ros_control.so">
      <robotNamespace>/simple_humanoid</robotNamespace>
    </plugin>
  </gazebo>

  <!-- Gazebo materials for visualization -->
  <gazebo reference="base_link">
    <material>Gazebo/Grey</material>
  </gazebo>

  <gazebo reference="head">
    <material>Gazebo/White</material>
  </gazebo>

  <gazebo reference="left_hip">
    <material>Gazebo/Blue</material>
  </gazebo>

  <gazebo reference="left_knee">
    <material>Gazebo/Blue</material>
  </gazebo>

  <gazebo reference="left_ankle">
    <material>Gazebo/Blue</material>
  </gazebo>

  <gazebo reference="right_hip">
    <material>Gazebo/Red</material>
  </gazebo>

  <gazebo reference="right_knee">
    <material>Gazebo/Red</material>
  </gazebo>

  <gazebo reference="right_ankle">
    <material>Gazebo/Red</material>
  </gazebo>

  <gazebo reference="left_shoulder">
    <material>Gazebo/Green</material>
  </gazebo>

  <gazebo reference="left_elbow">
    <material>Gazebo/Green</material>
  </gazebo>

  <gazebo reference="right_shoulder">
    <material>Gazebo/Yellow</material>
  </gazebo>

  <gazebo reference="right_elbow">
    <material>Gazebo/Yellow</material>
  </gazebo>

  <gazebo reference="imu_link">
    <material>Gazebo/Black</material>
  </gazebo>

</robot>